Traceback (most recent call last):
  File "/Users/sjt972/anaconda3/envs/poli-docs/lib/python3.9/site-packages/jupyter_cache/executors/utils.py", line 58, in single_nb_execution
    executenb(
  File "/Users/sjt972/anaconda3/envs/poli-docs/lib/python3.9/site-packages/nbclient/client.py", line 1305, in execute
    return NotebookClient(nb=nb, resources=resources, km=km, **kwargs).execute()
  File "/Users/sjt972/anaconda3/envs/poli-docs/lib/python3.9/site-packages/jupyter_core/utils/__init__.py", line 172, in wrapped
    return loop.run_until_complete(inner)
  File "/Users/sjt972/anaconda3/envs/poli-docs/lib/python3.9/asyncio/base_events.py", line 647, in run_until_complete
    return future.result()
  File "/Users/sjt972/anaconda3/envs/poli-docs/lib/python3.9/site-packages/nbclient/client.py", line 705, in async_execute
    await self.async_execute_cell(
  File "/Users/sjt972/anaconda3/envs/poli-docs/lib/python3.9/site-packages/nbclient/client.py", line 1058, in async_execute_cell
    await self._check_raise_for_error(cell, cell_index, exec_reply)
  File "/Users/sjt972/anaconda3/envs/poli-docs/lib/python3.9/site-packages/nbclient/client.py", line 914, in _check_raise_for_error
    raise CellExecutionError.from_cell_and_msg(cell, exec_reply_content)
nbclient.exceptions.CellExecutionError: An error occurred while executing the following cell:
------------------
from poli.core.registry import get_problems
get_problems(include_repository=True)
------------------


[0;31m---------------------------------------------------------------------------[0m
[0;31mTypeError[0m                                 Traceback (most recent call last)
Cell [0;32mIn[1], line 2[0m
[1;32m      1[0m [38;5;28;01mfrom[39;00m [38;5;21;01mpoli[39;00m[38;5;21;01m.[39;00m[38;5;21;01mcore[39;00m[38;5;21;01m.[39;00m[38;5;21;01mregistry[39;00m [38;5;28;01mimport[39;00m get_problems
[0;32m----> 2[0m [43mget_problems[49m[43m([49m[43minclude_repository[49m[38;5;241;43m=[39;49m[38;5;28;43;01mTrue[39;49;00m[43m)[49m

[0;31mTypeError[0m: get_problems() got an unexpected keyword argument 'include_repository'

