Traceback (most recent call last):
  File "/Users/sjt972/anaconda3/envs/poli-docs-310/lib/python3.10/site-packages/jupyter_cache/executors/utils.py", line 58, in single_nb_execution
    executenb(
  File "/Users/sjt972/anaconda3/envs/poli-docs-310/lib/python3.10/site-packages/nbclient/client.py", line 1314, in execute
    return NotebookClient(nb=nb, resources=resources, km=km, **kwargs).execute()
  File "/Users/sjt972/anaconda3/envs/poli-docs-310/lib/python3.10/site-packages/jupyter_core/utils/__init__.py", line 165, in wrapped
    return loop.run_until_complete(inner)
  File "/Users/sjt972/anaconda3/envs/poli-docs-310/lib/python3.10/asyncio/base_events.py", line 649, in run_until_complete
    return future.result()
  File "/Users/sjt972/anaconda3/envs/poli-docs-310/lib/python3.10/site-packages/nbclient/client.py", line 709, in async_execute
    await self.async_execute_cell(
  File "/Users/sjt972/anaconda3/envs/poli-docs-310/lib/python3.10/site-packages/nbclient/client.py", line 1062, in async_execute_cell
    await self._check_raise_for_error(cell, cell_index, exec_reply)
  File "/Users/sjt972/anaconda3/envs/poli-docs-310/lib/python3.10/site-packages/nbclient/client.py", line 918, in _check_raise_for_error
    raise CellExecutionError.from_cell_and_msg(cell, exec_reply_content)
nbclient.exceptions.CellExecutionError: An error occurred while executing the following cell:
------------------
import numpy as np

from poli.core.problem_setup_information import ProblemSetupInformation
from poli.core.util.abstract_observer import AbstractObserver

class SimpleObserver(AbstractObserver):
    def __init__(self):
        ...

    def initialize_observer(
        self,
        problem_setup_info: ProblemSetupInformation,
        caller_info: object,
        seed: int
    ) -> object:
        ...
    
    def observe(self, x: np.ndarray, y: np.ndarray, context=None) -> None:
        ...

    def finish(self) -> None:
        ...
------------------


[0;31m---------------------------------------------------------------------------[0m
[0;31mModuleNotFoundError[0m                       Traceback (most recent call last)
Cell [0;32mIn[1], line 3[0m
[1;32m      1[0m [38;5;28;01mimport[39;00m [38;5;21;01mnumpy[39;00m [38;5;28;01mas[39;00m [38;5;21;01mnp[39;00m
[0;32m----> 3[0m [38;5;28;01mfrom[39;00m [38;5;21;01mpoli[39;00m[38;5;21;01m.[39;00m[38;5;21;01mcore[39;00m[38;5;21;01m.[39;00m[38;5;21;01mproblem_setup_information[39;00m [38;5;28;01mimport[39;00m ProblemSetupInformation
[1;32m      4[0m [38;5;28;01mfrom[39;00m [38;5;21;01mpoli[39;00m[38;5;21;01m.[39;00m[38;5;21;01mcore[39;00m[38;5;21;01m.[39;00m[38;5;21;01mutil[39;00m[38;5;21;01m.[39;00m[38;5;21;01mabstract_observer[39;00m [38;5;28;01mimport[39;00m AbstractObserver
[1;32m      6[0m [38;5;28;01mclass[39;00m [38;5;21;01mSimpleObserver[39;00m(AbstractObserver):

[0;31mModuleNotFoundError[0m: No module named 'poli.core.problem_setup_information'

